Workbook

Sheet 1_System_Comparison
A1: System | B1: TP | C1: FN | D1: TN | E1: FP | F1: Sensitivity_% | G1: Specificity_% | H1: Precision_% | I1: Accuracy_% | J1: Accuracy_95CI | K1: F1_% | L1: Loc_On_Caught_% | M1: Loc_On_AllFaulty_% | N1: McNemar_p_vs_S0
A2: S0: Pure LLM Grader (Qwen2.5-7B V5) | B2: 30 | C2: 1 | D2: 15 | E2: 16 | F2: 96.77 | G2: 48.39 | H2: 65.22 | I2: 72.58 | J2: [61.3%, 83.9%] | K2: 77.92 | L2: 43.3% (13/30) | M2: 41.94 | N2: Baseline
A3: S1: Naive Regex + Tier-1 Exact | B3: 20 | C3: 11 | D3: 14 | E3: 17 | F3: 64.52 | G3: 45.16 | H3: 54.05 | I3: 54.84 | J3: [41.9%, 66.1%] | K3: 58.82 | L3: 40.0% (8/20) | M3: 25.81 | N3: 0.043285
A4: S2a: Pure LLM Step Parser + Two-Tier SymPy | B4: 24 | C4: 7 | D4: 24 | E4: 7 | F4: 77.42 | G4: 77.42 | H4: 77.42 | I4: 77.42 | J4: [66.1%, 87.1%] | K4: 77.42 | L4: 66.7% (16/24) | M4: 51.61 | N4: 0.690038
A5: S2b: Hybrid Parser + Tier-1 Exact Only | B5: 31 | C5: 0 | D5: 19 | E5: 12 | F5: 100 | G5: 61.29 | H5: 72.09 | I5: 80.65 | J5: [71.0%, 90.3%] | K5: 83.78 | L5: 90.3% (28/31) | M5: 90.32 | N5: 0.301758
A6: S3: Proposed Hybrid + Two-Tier Metrology | B6: 31 | C6: 0 | D6: 30 | E6: 1 | F6: 100 | G6: 96.77 | H6: 96.88 | I6: 98.39 | J6: [95.2%, 100.0%] | K6: 98.41 | L6: 100.0% (31/31) | M6: 100 | N6: 0.000145

Sheet 2_Question_Split_Eval
A1: Split | B1: System | C1: TP | D1: FN | E1: TN | F1: FP | G1: Sensitivity_% | H1: Specificity_% | I1: Precision_% | J1: Accuracy_% | K1: Accuracy_95CI | L1: F1_% | M1: Loc_On_Caught_% | N1: Loc_On_AllFaulty_% | O1: McNemar_p_vs_S0
A2: Calibration_Split (11 Odd Q, N=35) | B2: S0: Pure LLM Grader (Qwen2.5-7B V5) | C2: 16 | D2: 0 | E2: 9 | F2: 10 | G2: 100 | H2: 47.37 | I2: 61.54 | J2: 71.43 | K2: [57.1%, 85.7%] | L2: 76.19 | M2: 37.5% (6/16) | N2: 37.5 | O2: Baseline
A3: Calibration_Split (11 Odd Q, N=35) | B3: S1: Naive Regex + Tier-1 Exact | C3: 13 | D3: 3 | E3: 11 | F3: 8 | G3: 81.25 | H3: 57.89 | I3: 61.9 | J3: 68.57 | K3: [51.4%, 82.9%] | L3: 70.27 | M3: 38.5% (5/13) | N3: 31.25 | O3: 1
A4: Calibration_Split (11 Odd Q, N=35) | B4: S2a: Pure LLM Step Parser + Two-Tier SymPy | C4: 14 | D4: 2 | E4: 16 | F4: 3 | G4: 87.5 | H4: 84.21 | I4: 82.35 | J4: 85.71 | K4: [74.3%, 97.1%] | L4: 84.85 | M4: 64.3% (9/14) | N4: 56.25 | O4: 0.226562
A5: Calibration_Split (11 Odd Q, N=35) | B5: S2b: Hybrid Parser + Tier-1 Exact Only | C5: 16 | D5: 0 | E5: 12 | F5: 7 | G5: 100 | H5: 63.16 | I5: 69.57 | J5: 80 | K5: [65.7%, 91.4%] | L5: 82.05 | M5: 81.2% (13/16) | N5: 81.25 | O5: 0.548828
A6: Calibration_Split (11 Odd Q, N=35) | B6: S3: Proposed Hybrid + Two-Tier Metrology | C6: 16 | D6: 0 | E6: 18 | F6: 1 | G6: 100 | H6: 94.74 | I6: 94.12 | J6: 97.14 | K6: [91.4%, 100.0%] | L6: 96.97 | M6: 100.0% (16/16) | N6: 100 | O6: 0.011719
A7: HeldOut_Unseen_Test (11 Even Q, N=27) | B7: S0: Pure LLM Grader (Qwen2.5-7B V5) | C7: 14 | D7: 1 | E7: 6 | F7: 6 | G7: 93.33 | H7: 50 | I7: 70 | J7: 74.07 | K7: [55.6%, 88.9%] | L7: 80 | M7: 50.0% (7/14) | N7: 46.67 | O7: Baseline
A8: HeldOut_Unseen_Test (11 Even Q, N=27) | B8: S1: Naive Regex + Tier-1 Exact | C8: 7 | D8: 8 | E8: 3 | F8: 9 | G8: 46.67 | H8: 25 | I8: 43.75 | J8: 37.04 | K8: [18.5%, 55.6%] | L8: 45.16 | M8: 42.9% (3/7) | N8: 20 | O8: 0.006348
A9: HeldOut_Unseen_Test (11 Even Q, N=27) | B9: S2a: Pure LLM Step Parser + Two-Tier SymPy | C9: 10 | D9: 5 | E9: 8 | F9: 4 | G9: 66.67 | H9: 66.67 | I9: 71.43 | J9: 66.67 | K9: [48.1%, 85.2%] | L9: 68.97 | M9: 70.0% (7/10) | N9: 46.67 | O9: 0.790527
A10: HeldOut_Unseen_Test (11 Even Q, N=27) | B10: S2b: Hybrid Parser + Tier-1 Exact Only | C10: 15 | D10: 0 | E10: 7 | F10: 5 | G10: 100 | H10: 58.33 | I10: 75 | J10: 81.48 | K10: [66.7%, 92.6%] | L10: 85.71 | M10: 100.0% (15/15) | N10: 100 | O10: 0.625
A11: HeldOut_Unseen_Test (11 Even Q, N=27) | B11: S3: Proposed Hybrid + Two-Tier Metrology | C11: 15 | D11: 0 | E11: 12 | F11: 0 | G11: 100 | H11: 100 | I11: 100 | J11: 100 | K11: [100.0%, 100.0%] | L11: 100 | M11: 100.0% (15/15) | N11: 100 | O11: 0.015625

Sheet 3_Pedagogical_Summary
A1: Dimension | B1: Pure_LLM_Tutor_S0 | C1: Proposed_NeuroSymbolic_Tutor_S3
A2: Verdict Sensitivity (Recall on 31 Faulty) | B2: 96.8% (30/31) | C2: 100.0% (31/31)
A3: Verdict Specificity (Accept on 31 Correct) | B3: 48.4% (15/31) | C3: 96.8% (30/31)
A4: First-Error Localization (on Caught Faulty) | B4: 43.3% (13/30) | C4: 100.0% (31/31)
A5: Vietnamese Language Hygiene (Zero CJK Leakage) | B5: 100.0% (30/30) | C5: 100.0% (31/31)
A6: Anchor-Faithful Remediation (Expert Human Grade) | B6: ='9_Blind_Decoding_Key'!D33 | C6: ='9_Blind_Decoding_Key'!F33
A7: Pedagogical Usefulness Mean (1-3 Blind Human Rubric) | B7: ='9_Blind_Decoding_Key'!E33 | C7: ='9_Blind_Decoding_Key'!G33
A8: Pedagogical Rubric Levels 3 / 2 / 1 (Blind Count) | B8: ='9_Blind_Decoding_Key'!E34 | C8: ='9_Blind_Decoding_Key'!G34

Sheet 4_Tier_And_Error_Stats
A1: Category_Group | B1: Sub_Type | C1: Step_or_Case_Count
A2: Valid_Equivalence_Tier (31 Correct) | B2: Tier1_Exact_Symbolic | C2: 459
A3: Valid_Equivalence_Tier (31 Correct) | B3: Tier1_Wave_Symbolic | C3: 18
A4: Valid_Equivalence_Tier (31 Correct) | B4: Tier1_PiSq10_Symbolic | C4: 12
A5: Valid_Equivalence_Tier (31 Correct) | B5: Tier1_Exact_Numeric | C5: 6
A6: Valid_Equivalence_Tier (31 Correct) | B6: Tier2_HalfULP | C6: 5
A7: Valid_Equivalence_Tier (31 Correct) | B7: Tier2_PiApprox314 | C7: 4
A8: Detected_First_Error_Type (31 Faulty) | B8: IntraStep_Calc_Error | C8: 17
A9: Detected_First_Error_Type (31 Faulty) | B9: Canonical_State_Mismatch | C9: 4
A10: Detected_First_Error_Type (31 Faulty) | B10: Sequential_Value_Drift | C10: 3
A11: Detected_First_Error_Type (31 Faulty) | B11: Physical_Law_Error | C11: 2
A12: Detected_First_Error_Type (31 Faulty) | B12: Wave_Transform_Error | C12: 2
A13: Detected_First_Error_Type (31 Faulty) | B13: Initial_Wave_Mismatch | C13: 1
... A15: Detected_First_Error_Type (31 Faulty) | B15: Parametric_Solution_Error | C15: 1

Sheet 5_Parsing_Repair_Stats
A1: submission_id | B1: question_id | C1: ground_truth | D1: n_lines | E1: det_hops_total | F1: det_hops_compiled | G1: llm_assertions_raw | H1: llm_direct_compiled | I1: llm_1shot_repaired | J1: llm_unparsed_dropped | K1: hybrid_fused_compiled
A2: sub_01 | B2: q_04 | C2: SAI | D2: 5 | E2: 7 | F2: 7 | G2: 3 | H2: 3 | I2: 0 | J2: 0 | K2: 7
A3: sub_02 | B3: q_08 | C3: SAI | D3: 5 | E3: 13 | F3: 13 | G3: 3 | H3: 3 | I3: 0 | J3: 0 | K3: 13
A4: sub_03 | B4: q_10 | C4: SAI | D4: 7 | E4: 18 | F4: 18 | G4: 9 | H4: 9 | I4: 0 | J4: 0 | K4: 18
A5: sub_04 | B5: q_17 | C5: SAI | D5: 11 | E5: 13 | F5: 13 | G5: 4 | H5: 4 | I5: 0 | J5: 0 | K5: 13
A6: sub_05 | B6: q_19 | C6: SAI | D6: 9 | E6: 10 | F6: 10 | G6: 6 | H6: 6 | I6: 0 | J6: 0 | K6: 10
A7: sub_06 | B7: q_19 | C7: SAI | D7: 7 | E7: 9 | F7: 9 | G7: 4 | H7: 4 | I7: 0 | J7: 0 | K7: 9
A8: sub_07 | B8: q_20 | C8: SAI | D8: 7 | E8: 8 | F8: 8 | G8: 8 | H8: 8 | I8: 0 | J8: 0 | K8: 8
A9: sub_08 | B9: q_22 | C9: SAI | D9: 7 | E9: 12 | F9: 12 | G9: 3 | H9: 3 | I9: 0 | J9: 0 | K9: 12
A10: sub_09 | B10: q_25 | C10: SAI | D10: 4 | E10: 8 | F10: 6 | G10: 4 | H10: 4 | I10: 0 | J10: 0 | K10: 6
A11: sub_10 | B11: q_25 | C11: SAI | D11: 5 | E11: 9 | F11: 7 | G11: 4 | H11: 4 | I11: 0 | J11: 0 | K11: 7
A12: sub_11 | B12: q_26 | C12: SAI | D12: 11 | E12: 23 | F12: 23 | G12: 5 | H12: 5 | I12: 0 | J12: 0 | K12: 24
A13: sub_12 | B13: q_26 | C13: SAI | D13: 11 | E13: 23 | F13: 23 | G13: 4 | H13: 4 | I13: 0 | J13: 0 | K13: 24
... A63: cor_31 | B63: q_04 | C63: ĐÚNG | D63: 30 | E63: 14 | F63: 14 | G63: 12 | H63: 12 | I63: 0 | J63: 0 | K63: 18

Sheet 6_Detailed_62_Diagnostics
A1: submission_id | B1: question_id | C1: question_split | D1: student_model | E1: ground_truth | F1: canonical_final_answer | G1: S0_PureLLM_Verdict | H1: S0_Localized_Step | I1: S0_Loc_Correct | J1: S1_NaiveRegex_Verdict | K1: S1_Loc_Line | L1: S1_Loc_Correct | M1: S2a_PureLLMParser_Verdict | N1: S2a_Loc_Line | O1: S2a_Loc_Expr | P1: S2a_Loc_Correct | Q1: S2b_Tier1Exact_Verdict | R1: S2b_Loc_Line | S1: S2b_Loc_Expr | T1: S2b_Loc_Correct | U1: S3_Proposed_Verdict | V1: S3_Loc_Line | W1: S3_Loc_Expr | X1: S3_Error_Reason | Y1: S3_Expected_SymPy | Z1: S3_Loc_Correct
A2: sub_01 | B2: q_04 | C2: Calibration_11Q | D2: qwen1_5b | E2: SAI | F2: 0.25 | G2: INCORRECT | H2: Học sinh viết $\Delta t = \frac{2\pi}{\omega \cdot 2}$ nhưng Lời giải mẫu là $\Delta t = \frac{\pi}{\omega}$. | I2: 0 | J2: CORRECT | L2: 0 | M2: INCORRECT | N2: L04 | O2: Delta_t == 0.125 | P2: 1 | Q2: INCORRECT | R2: L04 | S2: \frac{\pi}{4\pi} == 0,125 \text{ (s)} | T2: 1 | U2: INCORRECT | V2: L04 | W2: \frac{\pi}{4\pi} == 0,125 \text{ (s)} | X2: IntraStep_Calc_Error (1/4 != 0.125000000000000, Numeric_Mismatch(diff=0.125,tol=1.00e-06)) | Y2: 1/4 | Z2: 1
A3: sub_02 | B3: q_08 | C3: HeldOut_Unseen_11Q | D3: qwen1_5b | E3: SAI | F3: 4 | G3: CORRECT | H3: Không có bước sai. | I3: 0 | J3: CORRECT | L3: 0 | M3: INCORRECT | N3: L02 | O3: omega**2 == 16*pi**2 / 8*pi | P3: 1 | Q3: INCORRECT | R3: L01 | S3: a_{max} == (\frac{v_{max}}{\omega})^2 | T3: 1 | U3: INCORRECT | V3: L01 | W3: a_{max} == (\frac{v_{max}}{\omega})^2 | X3: Physical_Law_Error (Symbolic_Mismatch) | Y3: A*omega**2 | Z3: 1
A4: sub_03 | B4: q_10 | C4: Calibration_11Q | D4: qwen1_5b | E4: SAI | F4: 10 | G4: INCORRECT | H4: Học sinh viết \( A = \sqrt{9 + 16 + 24} = \sqrt{49} = 7 \) cm nhưng Lời giải mẫu là \( A = \sqrt{9 + 16 - 24} = \sqrt{1} = 1 \) cm. | I4: 0 | J4: INCORRECT | K4: L02 | L4: 1 | M4: INCORRECT | N4: L02 | O4: x1 == 3*cos(10*t + pi/6) | P4: 1 | Q4: INCORRECT | R4: L02 | S4: x1 == 3cos(10t – π/3 + π/2) | T4: 1 | U4: INCORRECT | V4: L02 | W4: x1 == 3cos(10t – π/3 + π/2) | X4: Initial_Wave_Mismatch (Symbolic_Mismatch) | Y4: -3*cos(10*t + pi/6) | Z4: 1
A5: sub_04 | B5: q_17 | C5: HeldOut_Unseen_11Q | D5: qwen1_5b | E5: SAI | F5: 200*pi | G5: INCORRECT | H5: Học sinh viết \( v_{tb} = \frac{A\sqrt{3}}{\frac{T}{3}} = 9A/T \) nhưng Lời giải mẫu là \( v_{tb} = \frac{A\sqrt{3}}{\frac{T}{3}} = 3A\sqrt{3}/T \). | I5: 1 | J5: INCORRECT | K5: L09 | L5: 0 | M5: CORRECT | P5: 0 | Q5: INCORRECT | R5: L08 | S5: A.sqrt(3) / (T/3) == 9.A/T. | T5: 1 | U5: INCORRECT | V5: L08 | W5: A.sqrt(3) / (T/3) == 9.A/T. | X5: Symbolic_Simplification_Error (3*sqrt(3)*A/T != 9*A/T) | Y5: 3*sqrt(3)*A/T | Z5: 1
A6: sub_05 | B6: q_19 | C6: Calibration_11Q | D6: qwen1_5b | E6: SAI | F6: 0.245 | G6: INCORRECT | H6: Học sinh viết \( W = 0,02 + 0,1125\pi \, \text{J} \) nhưng Lời giải mẫu là \( W = 0,245 \, \text{J} \). | I6: 0 | J6: INCORRECT | K6: L04 | L6: 0 | M6: INCORRECT | N6: L05 | O6: W == 50*0.0004 + 0.2*(0.0225*5*pi) | P6: 1 | Q6: INCORRECT | R6: L05 | S6: W == 50.(0,0004) + 0,2.(0,0225 * 5π) | T6: 1 | U6: INCORRECT | V6: L05 | W6: W == 50.(0,0004) + 0,2.(0,0225 * 5π) | X6: Sequential_Value_Drift (W: prev=0.02 + 0.0225*pi**2 vs new=0.02 + 0.0225*pi) | Y6: 0.02 + 0.0225*pi**2 | Z6: 1
A7: sub_06 | B7: q_19 | C7: Calibration_11Q | D7: qwen3b | E7: SAI | F7: 0.245 | G7: INCORRECT | H7: Học sinh viết \( W = 50 \times (0,0004) + 0,2 \times (0,225 \times 5 \times 10) \) nhưng Lời giải mẫu là \( W = \frac{1}{2} \times 100 \times (0.02)^2 + \frac{1}{2} \times 0.4 \times (0.15\sqrt{5}\pi)^2 \). | I7: 1 | J7: INCORRECT | K7: L05 | L7: 1 | M7: INCORRECT | N7: L05 | O7: W == 50*0.0004 + 0.2*0.225*5*10 | P7: 1 | Q7: INCORRECT | R7: L05 | S7: W == 50.(0,0004) + 0,2.(0,225 * 5 * 10) | T7: 1 | U7: INCORRECT | V7: L05 | W7: W == 50.(0,0004) + 0,2.(0,225 * 5 * 10) | X7: Sequential_Value_Drift (W: prev=0.02 + 0.0225*pi**2 vs new=2.27000000000000) | Y7: 0.02 + 0.0225*pi**2 | Z7: 1
A8: sub_07 | B8: q_20 | C8: HeldOut_Unseen_11Q | D8: qwen1_5b | E8: SAI | F8: 0.00036 | G8: INCORRECT | H8: Học sinh viết \( W_{\text{đmax}} = \frac{1}{2} \cdot 0.05 \cdot 3^2 \cdot 0.04^2 \) nhưng Lời giải mẫu là \( W_{\text{đmax}} = \frac{1}{2} \cdot 0.05 \cdot (0.12)^2 \). | I8: 0 | J8: INCORRECT | K8: L02 | L8: 0 | M8: INCORRECT | N8: L06 | O8: Wdjmax == 0.00225 | P8: 1 | Q8: INCORRECT | R8: L06 | S8: Wd_max == 0,00225 (J). | T8: 1 | U8: INCORRECT | V8: L06 | W8: Wd_max == 0,00225 (J). | X8: Sequential_Value_Drift (Wd_max: prev=0.000360000000000000 vs new=0.00225000000000000) | Y8: 0.000360000000000000 | Z8: 1
A9: sub_08 | B9: q_22 | C9: Calibration_11Q | D9: qwen3b | E9: SAI | F9: 0.075 | G9: INCORRECT | H9: Học sinh viết \(\alpha_0^2 = \frac{0.441}{78.4}\) nhưng Lời giải mẫu là \(\alpha_0^2 = \frac{0.441}{78.4}\). (Bước này tương đương toán học.) | I9: 0 | J9: INCORRECT | K9: L02 | L9: 0 | M9: INCORRECT | N9: L06 | O9: alpha0 == sqrt(0.00565625) | P9: 0 | Q9: INCORRECT | R9: L05 | S9: alpha0^2 == 0,00565625. | T9: 1 | U9: INCORRECT | V9: L05 | W9: alpha0^2 == 0,00565625. | X9: IntraStep_Calc_Error (9/1600 != 0.00565625000000000, Numeric_Mismatch(diff=3.125e-05,tol=1.00e-06)) | Y9: 9/1600 | Z9: 1
A10: sub_09 | B10: q_25 | C10: HeldOut_Unseen_11Q | D10: qwen1_5b | E10: SAI | F10: 4.08 | G10: INCORRECT | H10: Học sinh viết \( \frac{A'}{A} = \sqrt{0.92} \approx 0.9539 \) nhưng Lời giải mẫu là \( \frac{A'}{A} = \sqrt{0.92} \approx 0.9592 \). | I10: 1 | J10: CORRECT | L10: 0 | M10: CORRECT | P10: 0 | Q10: INCORRECT | R10: L02 | S10: sqrt(0,92) == 0,9539. | T10: 1 | U10: INCORRECT | V10: L02 | W10: sqrt(0,92) == 0,9539. | X10: IntraStep_Calc_Error (0.959166304662544 != 0.953900000000000, Numeric_Mismatch(diff=0.0052663,tol=5.50e-05)) | Y10: 0.959166304662544 | Z10: 1
A11: sub_10 | B11: q_25 | C11: HeldOut_Unseen_11Q | D11: qwen3b | E11: SAI | F11: 4.08 | G11: INCORRECT | H11: Học sinh viết \( \frac{A'}{A} \approx 0.9583 \) nhưng Lời giải mẫu là \( \frac{A'}{A} \approx 0.9592 \). | I11: 1 | J11: CORRECT | L11: 0 | M11: CORRECT | P11: 0 | Q11: INCORRECT | R11: L03 | S11: sqrt(0,92) == 0,9583. | T11: 1 | U11: INCORRECT | V11: L03 | W11: sqrt(0,92) == 0,9583. | X11: IntraStep_Calc_Error (0.959166304662544 != 0.958300000000000, Numeric_Mismatch(diff=0.0008663,tol=5.50e-05)) | Y11: 0.959166304662544 | Z11: 1
A12: sub_11 | B12: q_26 | C12: Calibration_11Q | D12: qwen1_5b | E12: SAI | F12: 27 | G12: INCORRECT | H12: Học sinh viết \(\Delta t = t_1 + T = \frac{T}{6} + T = \frac{7T}{6} = \frac{7 \cdot 1}{6} = 1.167\) (s) nhưng Lời giải mẫu là \(\Delta t = t_1 + T = \frac{T}{6} + T = 0.167 + 1 = 1.167\) (s). | I12: 0 | J12: INCORRECT | K12: L08 | L12: 0 | M12: INCORRECT | N12: L10 | O12: v_tb == 31.5/1.167 | P12: 1 | Q12: INCORRECT | R12: L08 | S12: (7 . 1) / 6 == 1,167 (s). | T12: 0 | U12: INCORRECT | V12: L10 | W12: 31,5 / 1,167 == 27,19 (cm/s). | X12: IntraStep_Calc_Error (26.9922879177378 != 27.1900000000000, Numeric_Mismatch(diff=0.19771,tol=5.50e-03)) | Y12: 26.9922879177378 | Z12: 1
A13: sub_12 | B13: q_26 | C13: Calibration_11Q | D13: qwen3b | E13: SAI | F13: 27 | G13: INCORRECT | H13: Học sinh viết \(\Delta t = \frac{7T}{6} = \frac{7 \cdot 1}{6} = \frac{7}{6} \text{ s}\) nhưng Lời giải mẫu là \(\Delta t = t_1 + T = \frac{T}{6} + T = \frac{1}{6} + 1 = 1.167 \text{ s}\). | I13: 0 | J13: CORRECT | L13: 0 | M13: CORRECT | P13: 0 | Q13: INCORRECT | R13: L10 | S13: 31,5 / 7/6 == 25,5 (cm/s). | T13: 1 | U13: INCORRECT | V13: L10 | W13: 31,5 / 7/6 == 25,5 (cm/s). | X13: IntraStep_Calc_Error (27.0000000000000 != 25.5000000000000, Numeric_Mismatch(diff=1.5,tol=5.50e-02)) | Y13: 27.0000000000000 | Z13: 1
A14: sub_13 | B14: q_28 | C14: HeldOut_Unseen_11Q | D14: qwen3b | E14: SAI | F14: 0.25 | G14: INCORRECT | H14: Học sinh viết \(\omega = \frac{2\pi}{60} = \frac{\pi}{30} \text{ rad/s}\) và \(T = 60 \text{ s}\), nhưng Lời giải mẫu là \(\omega = \frac{200\pi}{60} = \frac{10\pi}{3} \text{ rad/s}\) và \(T = 0.6 \text{ s}\). | I14: 1 | J14: INCORRECT | K14: L01 | L14: 1 | M14: INCORRECT | N14: L01 | O14: omega == pi/30 | P14: 1 | Q14: INCORRECT | R14: L01 | S14: a_max / v_max == 2.pi / 60 | T14: 1 | U14: INCORRECT | V14: L01 | W14: a_max / v_max == 2.pi / 60 | X14: IntraStep_Calc_Error (10*pi/3 != pi/30, Numeric_Mismatch(diff=10.367,tol=1.00e-06)) | Y14: 10*pi/3 | Z14: 1
A15: sub_14 | B15: q_28 | C15: HeldOut_Unseen_11Q | D15: qwen7b | E15: SAI | F15: 0.25 | G15: INCORRECT | H15: Học sinh viết \(t = \frac{5T}{12}\) nhưng Lời giải mẫu là \(t = \frac{T}{12} + \frac{T}{4} + \frac{T}{12} = \frac{5T}{12}\). Tuy nhiên, học sinh đã tính sai tổng thời gian di chuyển, kết quả là \(t = 0.3\) s thay vì \(t = 0.25\) s. | I15: 1 | J15: CORRECT | L15: 0 | M15: INCORRECT | N15: L11 | O15: t == 3/10 | P15: 1 | Q15: INCORRECT | R15: L10 | S15: t_1 + t_2 + t_3 == \frac{T}{12} + \frac{T}{4} + \frac{T}{12} | T15: 1 | U15: INCORRECT | V15: L11 | W15: \frac{5 \times 0.6}{12} == \frac{3}{10} | X15: IntraStep_Calc_Error (0.250000000000000 != 3/10, Numeric_Mismatch(diff=0.05,tol=1.00e-06)) | Y15: 0.250000000000000 | Z15: 1
A16: sub_15 | B16: q_29 | C16: Calibration_11Q | D16: qwen1_5b | E16: SAI | F16: 7/24 | G16: INCORRECT | H16: Học sinh viết \(\Delta\phi = \frac{3\pi}{2}\) rad nhưng Lời giải mẫu là \(\Delta\phi = \frac{7\pi}{6}\) rad. | I16: 0 | J16: INCORRECT | K16: L01 | L16: 0 | M16: INCORRECT | N16: L05 | O16: delta_phi == 3*pi/2 | P16: 0 | Q16: INCORRECT | R16: L02 | S16: phi1 == -π/6 rad. | T16: 1 | U16: INCORRECT | V16: L02 | W16: phi1 == -π/6 rad. | X16: Canonical_State_Mismatch (phi1=-pi/6 vs gold=-pi/3) | Y16: -pi/3 | Z16: 1
A17: sub_16 | B17: q_30 | C17: HeldOut_Unseen_11Q | D17: qwen3b | E17: SAI | F17: 403.4 | G17: INCORRECT | H17: Học sinh viết t1 = 1,047 / 5π ≈ 0,066 s nhưng Lời giải mẫu là t1 = 1/5 = 0,2 s. | I17: 0 | J17: INCORRECT | K17: L02 | L17: 0 | M17: CORRECT | P17: 0 | Q17: INCORRECT | R17: L06 | S17: 2π/3 + π/3 == 1,047 rad. | T17: 1 | U17: INCORRECT | V17: L06 | W17: 2π/3 + π/3 == 1,047 rad. | X17: IntraStep_Calc_Error (pi != 1.04700000000000, Numeric_Mismatch(diff=2.0946,tol=5.50e-04)) | Y17: pi | Z17: 1
A18: sub_17 | B18: q_31 | C18: Calibration_11Q | D18: qwen1_5b | E18: SAI | F18: 140.66 | G18: INCORRECT | H18: Học sinh viết \( S = A(2 - \frac{\sqrt{3}}{2}) \) nhưng Lời giải mẫu là \( S = A(2 - \sqrt{3}) \). | I18: 1 | J18: CORRECT | L18: 0 | M18: INCORRECT | N18: L06 | O18: S == A*(2 - sqrt(3)/2) | P18: 1 | Q18: INCORRECT | R18: L06 | S18: S == A(2 - \frac{\sqrt{3}}{2}) | T18: 1 | U18: INCORRECT | V18: L06 | W18: S == A(2 - \frac{\sqrt{3}}{2}) | X18: Canonical_State_Mismatch (S=6*(2 - sqrt(3)/2)/(2 - sqrt(3)) vs gold=6) | Y18: 6 | Z18: 1
A19: sub_18 | B19: q_31 | C19: Calibration_11Q | D19: qwen3b | E19: SAI | F19: 140.66 | G19: INCORRECT | H19: Học sinh viết Chu kỳ \( T = 0,5 \) s và tần số góc \( \omega = 4\pi \) rad/s, nhưng Lời giải mẫu là Chu kỳ \( T = 1 \) s và tần số góc \( \omega = 2\pi \) rad/s. | I19: 1 | J19: INCORRECT | K19: L07 | L19: 0 | M19: INCORRECT | N19: L03 | O19: T == 0.5 | P19: 1 | Q19: INCORRECT | R19: L03 | S19: T == 0,5 s | T19: 1 | U19: INCORRECT | V19: L03 | W19: T == 0,5 s | X19: Canonical_State_Mismatch (T=0.500000000000000 vs gold=1) | Y19: 1 | Z19: 1
A20: sub_19 | B20: q_32 | C20: HeldOut_Unseen_11Q | D20: qwen1_5b | E20: SAI | F20: T/8 | G20: INCORRECT | H20: Học sinh viết \( t = \frac{T}{4} \) nhưng Lời giải mẫu là \( t = \frac{T}{8} \). | I20: 0 | J20: CORRECT | L20: 0 | M20: CORRECT | P20: 0 | Q20: INCORRECT | R20: L05 | S20: Wd == \frac{1}{2} k x^{2} | T20: 1 | U20: INCORRECT | V20: L05 | W20: Wd == \frac{1}{2} k x^{2} | X20: Physical_Law_Error (Symbolic_Mismatch) | Y20: k*(A**2 - x**2)/2 | Z20: 1
A21: sub_20 | B21: q_33 | C21: Calibration_11Q | D21: qwen1_5b | E21: SAI | F21: 1000 | G21: INCORRECT | H21: Học sinh viết \(\left(\frac{10\pi}{10\sqrt{2}\pi}\right)^2 + \left(\frac{a}{100\pi^2 \sqrt{2}}\right)^2 = 1\) nhưng Lời giải mẫu là \(\left(\frac{v}{v_{\text{max}}}\right)^2 + \left(\frac{a}{a_{\text{max}}}\right)^2 = 1\). | I21: 0 | J21: INCORRECT | K21: L05 | L21: 0 | M21: INCORRECT | N21: L05 | O21: (10*pi/10*sqrt(2)*pi)**2 + (a/(100*pi**2*sqrt(2)))**2 == 1 | P21: 0 | Q21: INCORRECT | R21: L05 | S21: (10π / 10√2 π)^2 + (a / 100π^2 . √2)^2 == 1. | T21: 0 | U21: INCORRECT | V21: L06 | W21: 1/4 + (a / 100π^2 . √2)^2 == 1 | X21: IntraStep_Calc_Error (9/4 != 1, Numeric_Mismatch(diff=1.25,tol=5.50e-01)) | Y21: 9/4 | Z21: 1
A22: sub_21 | B22: q_33 | C22: Calibration_11Q | D22: qwen3b | E22: SAI | F22: 1000 | G22: INCORRECT | H22: Học sinh viết \(|a| = 100\pi^2\sqrt{2} / \sqrt{2} = 100\pi^2\) nhưng Lời giải mẫu là \(|a| = 100\pi^2\). | I22: 0 | J22: INCORRECT | K22: L01 | L22: 0 | M22: INCORRECT | N22: L06 | O22: (10*pi / 10*pi*sqrt(2))**2 + (a / 100*pi**2*sqrt(2))**2 == 1 | P22: 0 | Q22: INCORRECT | R22: L09 | S22: π^2 == 9,87 | T22: 1 | U22: INCORRECT | V22: L09 | W22: |a| == 100 . 9,87 . 1,41 | X22: IntraStep_Calc_Error (100*pi**2 != 1391.67000000000, Numeric_Mismatch(diff=404.71,tol=1.00e-06)) | Y22: 100*pi**2 | Z22: 1
A23: sub_22 | B23: q_34 | C23: HeldOut_Unseen_11Q | D23: qwen1_5b | E23: SAI | F23: 0.5 | G23: INCORRECT | H23: Học sinh viết \(\omega = \frac{vx}{\sqrt{75}}\) nhưng Lời giải mẫu là \(\omega = 4\pi\). | I23: 0 | J23: CORRECT | L23: 0 | M23: INCORRECT | N23: L13 | O23: T == pi * sqrt(75) / 10 | P23: 1 | Q23: INCORRECT | R23: L13 | S23: 2π * √75 / (20π√3) == π * √75 / 10 | T23: 1 | U23: INCORRECT | V23: L13 | W23: 2π * √75 / (20π√3) == π * √75 / 10 | X23: IntraStep_Calc_Error (1/2 != sqrt(3)*pi/2, Numeric_Mismatch(diff=2.2207,tol=1.00e-06)) | Y23: 1/2 | Z23: 1
A24: sub_23 | B24: q_35 | C24: Calibration_11Q | D24: qwen1_5b | E24: SAI | F24: {'A': 6, 'omega': 20} | G24: INCORRECT | H24: Học sinh viết \(\omega = \sqrt{\frac{9}{3600}} = \sqrt{\frac{1}{400}} = \frac{1}{20} \text{ rad/s}\) nhưng Lời giải mẫu là \(\omega = \sqrt{\frac{3600}{9}} = \sqrt{400} = 20 \text{ rad/s}\). | I24: 1 | J24: INCORRECT | K24: L09 | L24: 1 | M24: INCORRECT | N24: L09 | O24: omega == sqrt((x_2**2 - x_1**2)/(v_1**2 - v_2**2)) | P24: 1 | Q24: INCORRECT | R24: L09 | S24: \omega == \sqrt{\frac{x_2^2 - x_1^2}{v_1^2 - v_2^2}} | T24: 1 | U24: INCORRECT | V24: L09 | W24: \omega == \sqrt{\frac{x_2^2 - x_1^2}{v_1^2 - v_2^2}} | X24: Canonical_State_Mismatch (omega=1/20 vs gold=20) | Y24: 20 | Z24: 1
A25: sub_24 | B25: q_35 | C25: Calibration_11Q | D25: qwen3b | E25: SAI | F25: {'A': 6, 'omega': 20} | G25: INCORRECT | H25: Học sinh viết \( A^2 = 9 + \frac{9}{4} = \frac{45}{4} \) nhưng Lời giải mẫu là \( A^2 = 9 + 27 = 36 \). | I25: 1 | J25: INCORRECT | K25: L03 | L25: 0 | M25: INCORRECT | N25: L03 | O25: (v1/omega)**2 == (v2/omega)**2 | P25: 0 | Q25: INCORRECT | R25: L08 | S25: (-60.sqrt(3) / 20)^2 == 900 / 400 | T25: 1 | U25: INCORRECT | V25: L08 | W25: (-60.sqrt(3) / 20)^2 == 900 / 400 | X25: IntraStep_Calc_Error (27 != 9/4, Numeric_Mismatch(diff=24.75,tol=1.00e-06)) | Y25: 27 | Z25: 1
A26: sub_25 | B26: q_36 | C26: HeldOut_Unseen_11Q | D26: qwen1_5b | E26: SAI | F26: 1/12 | G26: INCORRECT | H26: Học sinh viết \( x = -\frac{1}{2}A \) nhưng Lời giải mẫu là \( x = \frac{A}{2} \). | I26: 1 | J26: INCORRECT | K26: L09 | L26: 0 | M26: INCORRECT | N26: L14 | O26: max(a) == (4*pi)**2*A | P26: 0 | Q26: INCORRECT | R26: L25 | S26: ωt == π | T26: 1 | U26: INCORRECT | V26: L25 | W26: ωt == π | X26: IntraStep_Calc_Error (pi/3 != pi, Numeric_Mismatch(diff=2.0944,tol=1.00e-06)) | Y26: pi/3 | Z26: 1
A27: sub_26 | B27: q_37 | C27: Calibration_11Q | D27: qwen3b | E27: SAI | F27: 0.06*sqrt(2) | G27: INCORRECT | H27: Học sinh viết \(A = \frac{0.6 \times \sqrt{2}}{10}\) nhưng Lời giải mẫu là \(A = \frac{0.6 \times \sqrt{2}}{10.0}\). | I27: 0 | J27: INCORRECT | K27: L04 | L27: 1 | M27: CORRECT | P27: 0 | Q27: INCORRECT | R27: L04 | S27: (0,6 * sqrt(2)) / 10 == 0,077 (m). | T27: 1 | U27: INCORRECT | V27: L04 | W27: (0,6 * sqrt(2)) / 10 == 0,077 (m). | X27: IntraStep_Calc_Error (0.06*sqrt(2) != 0.0770000000000000, Numeric_Mismatch(diff=0.0078528,tol=5.50e-04)) | Y27: 0.06*sqrt(2) | Z27: 1
A28: sub_27 | B28: q_38 | C28: HeldOut_Unseen_11Q | D28: qwen1_5b | E28: SAI | F28: 1 | G28: INCORRECT | H28: Học sinh viết \( \omega^2 = 20 \) nhưng Lời giải mẫu là \( \omega^2 = 40 \). | I28: 0 | J28: CORRECT | L28: 0 | M28: INCORRECT | N28: L06 | O28: 100 == omega**2 * 5 | P28: 0 | Q28: INCORRECT | R28: L03 | S28: A/2 == 5 cm. | T28: 1 | U28: INCORRECT | V28: L03 | W28: A/2 == 5 cm. | X28: IntraStep_Calc_Error (5/2 != 5, Numeric_Mismatch(diff=2.5,tol=5.50e-01)) | Y28: 5/2 | Z28: 1
A29: sub_28 | B29: q_39 | C29: Calibration_11Q | D29: qwen1_5b | E29: SAI | F29: 5*cos(pi*t - pi/3) | G29: INCORRECT | H29: Học sinh viết \( \omega = 3\sqrt{10} \) rad/s nhưng Lời giải mẫu là \( \omega = \pi \) rad/s. | I29: 1 | J29: INCORRECT | K29: L14 | L29: 1 | M29: INCORRECT | N29: L16 | O29: omega == 3*sqrt(10) | P29: 1 | Q29: INCORRECT | R29: L04 | S29: \omega^2 == 250 / 25 | T29: 0 | U29: INCORRECT | V29: L14 | W29: \omega \cdot \frac{2}{3} + \phi == \pi/3 | X29: IntraStep_Calc_Error (pi != pi/3, Numeric_Mismatch(diff=2.0944,tol=1.00e-06)) | Y29: pi | Z29: 1
A30: sub_29 | B30: q_40 | C30: HeldOut_Unseen_11Q | D30: qwen1_5b | E30: SAI | F30: 1/6 | G30: INCORRECT | H30: Học sinh viết \( v = 20\pi \cos(10\pi t + \frac{5\pi}{6}) \) nhưng Lời giải mẫu là \( v = 20\pi \cos(10\pi t + \frac{\pi}{6}) \). | I30: 0 | J30: CORRECT | L30: 0 | M30: INCORRECT | N30: L03 | O30: v == 20*pi*cos(10*pi*t + pi/6) | P30: 0 | Q30: INCORRECT | R30: L02 | S30: -\omega A \sin(\omega t + \phi) == -\omega A \cos(\omega t + \phi + \frac{\pi}{2}) | T30: 1 | U30: INCORRECT | V30: L02 | W30: -\omega A \sin(\omega t + \phi) == -\omega A \cos(\omega t + \phi + \frac{\pi}{2}) | X30: Wave_Transform_Error (Symbolic_Mismatch) | Y30: -A*omega*sin(omega*t + phi) | Z30: 1
A31: sub_30 | B31: q_40 | C31: HeldOut_Unseen_11Q | D31: qwen3b | E31: SAI | F31: 1/6 | G31: INCORRECT | H31: Học sinh viết \( t = -\frac{\pi}{30} + \frac{1}{2} \) nhưng Lời giải mẫu là \( t = \frac{-1 + 6k}{30} \) với \( k = 1 \). | I31: 1 | J31: INCORRECT | K31: L08 | L31: 1 | M31: INCORRECT | N31: L08 | O31: t == -pi/30 + k/2 | P31: 1 | Q31: INCORRECT | R31: L08 | S31: t == -π/30 + k/2. | T31: 1 | U31: INCORRECT | V31: L08 | W31: t == -π/30 + k/2. | X31: Parametric_Solution_Error (k/2 - pi/30 != (2*pi*k - pi/3)/(10*pi)) | Y31: k/5 - 1/30 | Z31: 1
A32: sub_31 | B32: q_40 | C32: HeldOut_Unseen_11Q | D32: qwen7b | E32: SAI | F32: 1/6 | G32: INCORRECT | H32: Học sinh viết \(10\pi t = -\frac{\pi}{6} + \frac{\pi}{6} + 2k\pi\) nhưng Lời giải mẫu là \(10\pi t = -\frac{\pi}{3} + 2k\pi\). | I32: 0 | J32: INCORRECT | K32: L03 | L32: 1 | M32: INCORRECT | N32: L03 | O32: v == 40*pi*cos(10*pi*t - pi/6) | P32: 1 | Q32: INCORRECT | R32: L03 | S32: 40π.cos(10πt - π/3 + π/2) == 40π.cos(10πt - π/6). | T32: 1 | U32: INCORRECT | V32: L03 | W32: 40π.cos(10πt - π/3 + π/2) == 40π.cos(10πt - π/6). | X32: Wave_Transform_Error (Symbolic_Mismatch) | Y32: 40*pi*cos(pi*(10*t + 1/6)) | Z32: 1
A33: cor_01 | B33: q_04 | C33: Calibration_11Q | D33: qwen7b | E33: ĐÚNG | F33: 0.25 | G33: INCORRECT | H33: Học sinh viết $\Delta t = \frac{2\pi}{\omega \cdot 2}$ nhưng Lời giải mẫu là $\Delta t = \frac{\pi}{\omega}$. | J33: CORRECT | M33: CORRECT | Q33: CORRECT | U33: CORRECT | X33: All_Steps_Verified_OK
A34: cor_02 | B34: q_08 | C34: HeldOut_Unseen_11Q | D34: qwen7b | E34: ĐÚNG | F34: 4 | G34: CORRECT | H34: Không có bước sai. | J34: CORRECT | M34: INCORRECT | N34: L02 | O34: omega == 16*pi**2/8*pi | Q34: CORRECT | U34: CORRECT | X34: All_Steps_Verified_OK
A35: cor_03 | B35: q_10 | C35: Calibration_11Q | D35: qwen7b | E35: ĐÚNG | F35: 10 | G35: INCORRECT | H35: Học sinh viết \( x_1 = 3\cos(10t - \frac{5\pi}{6}) \) cm nhưng Lời giải mẫu là \( x_1 = 3\sin(10t - \frac{\pi}{3}) \) cm. | J35: INCORRECT | K35: L03 | M35: CORRECT | Q35: CORRECT | U35: CORRECT | X35: All_Steps_Verified_OK
A36: cor_04 | B36: q_17 | C36: HeldOut_Unseen_11Q | D36: qwen7b | E36: ĐÚNG | F36: 200*pi | G36: CORRECT | H36: Không có bước sai. | J36: INCORRECT | K36: L09 | M36: CORRECT | Q36: CORRECT | U36: CORRECT | X36: All_Steps_Verified_OK
A37: cor_05 | B37: q_19 | C37: Calibration_11Q | D37: qwen7b | E37: ĐÚNG | F37: 0.245 | G37: CORRECT | H37: Không có bước sai. | J37: INCORRECT | K37: L04 | M37: CORRECT | Q37: INCORRECT | R37: L05 | S37: W == 50.(0,0004) + 0,2.(0,0225 * 5 * 10) | U37: CORRECT | X37: All_Steps_Verified_OK
A38: cor_06 | B38: q_19 | C38: Calibration_11Q | D38: gpt4o | E38: ĐÚNG | F38: 0.245 | G38: CORRECT | H38: Không có bước sai. | J38: CORRECT | M38: CORRECT | Q38: INCORRECT | R38: L18 | S38: 0,0225 \times 5 \times \pi^2 == 0,1125 \times 10 | U38: CORRECT | X38: All_Steps_Verified_OK
A39: cor_07 | B39: q_20 | C39: HeldOut_Unseen_11Q | D39: qwen7b | E39: ĐÚNG | F39: 0.00036 | G39: CORRECT | H39: Không có bước sai. | J39: INCORRECT | K39: L02 | M39: CORRECT | Q39: CORRECT | U39: CORRECT | X39: All_Steps_Verified_OK
A40: cor_08 | B40: q_22 | C40: Calibration_11Q | D40: qwen7b | E40: ĐÚNG | F40: 0.075 | G40: CORRECT | H40: Không có bước sai. | J40: CORRECT | M40: CORRECT | Q40: CORRECT | U40: CORRECT | X40: All_Steps_Verified_OK
...

Sheet 7_Remediation_31_Faulty
A1: submission_id | B1: question_id | C1: question_split | D1: S0_PureLLM_Verdict | E1: S0_Localized_Step | F1: S0_Remediation_Fix | G1: S0_Loc_Correct | H1: S0_Expert_Faithful | I1: S0_Expert_Usefulness_1to3 | J1: S3_SymPy_Verdict | K1: S3_Loc_Line | L1: S3_Loc_Expr | M1: S3_Error_Reason | N1: S3_ReAnchored_Remediation | O1: S3_Loc_Correct | P1: S3_Vietnamese_Clean | Q1: S3_Has_Socratic_Question
A2: sub_01 | B2: q_04 | C2: Calibration_11Q | D2: INCORRECT | E2: Học sinh viết $\Delta t = \frac{2\pi}{\omega \cdot 2}$ nhưng Lời giải mẫu là $\Delta t = \frac{\pi}{\omega}$. | F2: Học sinh nên sử dụng công thức $\Delta t = \frac{\pi}{\omega}$ thay vì $\Delta t = \frac{2\pi}{\omega \cdot 2}$. | G2: 0 | H2: 0 | I2: 1 | J2: INCORRECT | K2: L04 | L2: \frac{\pi}{4\pi} == 0,125 \text{ (s)} | M2: IntraStep_Calc_Error (1/4 != 0.125000000000000, Numeric_Mismatch(diff=0.125,tol=1.00e-06)) | N2: Dòng L04 có lỗi ở chỗ học sinh đã thực hiện phép chia \(\frac{\pi}{4\pi}\) và thu được kết quả \(0.125\) thay vì \(0.25\). Theo công thức chuẩn, chu kỳ \(T\) của dao động là \(\frac{2\pi}{\omega}\), và khoảng thời gian giữa hai lần liên tiếp vật đi qua VTCB là \(\Delta t = \frac{T}{2} = \frac{\pi}{\omega}\). Vì vậy, khi thay \(\omega = 4\pi\) vào, ta sẽ có \(\Delta t = \frac{\pi}{4\pi} = \frac{1}{4} = 0.25\) s. Hãy kiểm tra lại phép tính của bạn và xem liệu bạn có làm tròn sai hay không? ? | O2: 1 | P2: 1 | Q2: 1
A3: sub_02 | B3: q_08 | C3: HeldOut_Unseen_11Q | D3: CORRECT | E3: Không có bước sai. | F3: Không cần sửa gì. | G3: 0 | J3: INCORRECT | K3: L01 | L3: a_{max} == (\frac{v_{max}}{\omega})^2 | M3: Physical_Law_Error (Symbolic_Mismatch) | N3: Dòng L01 của em có vấn đề. Em đã viết \( a_{max} = \left(\frac{v_{max}}{\omega}\right)^2 \), nhưng theo lời giải chuẩn, công thức đúng là \( a_{max} = \omega^2 A \). Vì vậy, em nên sử dụng mối quan hệ giữa \( a_{max} \), \( \omega \), và \( A \) để tìm \( \omega \) trước. Cụ thể, em có thể viết \( \omega^2 = \frac{a_{max}}{A} \). Vậy, em hãy thử lại từ đây xem sao? | O3: 1 | P3: 1 | Q3: 1
A4: sub_03 | B4: q_10 | C4: Calibration_11Q | D4: INCORRECT | E4: Học sinh viết \( A = \sqrt{9 + 16 + 24} = \sqrt{49} = 7 \) cm nhưng Lời giải mẫu là \( A = \sqrt{9 + 16 - 24} = \sqrt{1} = 1 \) cm. | F4: Học sinh cần lưu ý rằng độ lệch pha \( \Delta \phi = \pi \) rad, nên \( \cos(\Delta \phi) = \cos(\pi) = -1 \). Do đó, biểu thức cho biên độ tổng hợp \( A \) phải là \( A = \sqrt{9 + 16 + 2 \cdot 3 \cdot 4 \cdot (-1)} = \sqrt{1} = 1 \) cm. | G4: 0 | H4: 1 | I4: 2 | J4: INCORRECT | K4: L02 | L4: x1 == 3cos(10t – π/3 + π/2) | M4: Initial_Wave_Mismatch (Symbolic_Mismatch) | N4: Dòng L02 có vấn đề. Học sinh đã chuẩn hóa phương trình \( x_1 \) thành \( 3\cos(10t - \frac{\pi}{3} + \frac{\pi}{2}) \), nhưng theo công thức chuẩn, ta cần cộng thêm \( \frac{\pi}{2} \) vào pha của \( x_1 \) để chuyển nó sang dạng cos. Tuy nhiên, học sinh đã cộng \( \frac{\pi}{2} \) vào pha \( -\frac{\pi}{3} \) mà không đổi dấu, dẫn đến sai lệch. Theo công thức chuẩn, pha của \( x_1 \) sau khi chuẩn hóa nên là \( -\frac{\pi}{3} - \frac{\pi}{2} = -\frac{5\pi}{6} \). Hãy kiểm tra lại và viết lại pha của \( x_1 \) sao cho nó đúng theo công thức chuẩn, rồi tiếp tục tính toán nhé? | O4: 1 | P4: 1 | Q4: 1
A5: sub_04 | B5: q_17 | C5: HeldOut_Unseen_11Q | D5: INCORRECT | E5: Học sinh viết \( v_{tb} = \frac{A\sqrt{3}}{\frac{T}{3}} = 9A/T \) nhưng Lời giải mẫu là \( v_{tb} = \frac{A\sqrt{3}}{\frac{T}{3}} = 3A\sqrt{3}/T \). | F5: Học sinh nên sử dụng công thức \( v_{tb} = \frac{S}{\Delta t} = \frac{A\sqrt{3}}{\frac{T}{3}} = 3A\sqrt{3}/T \) như trong Lời giải mẫu. | G5: 1 | H5: 1 | I5: 3 | J5: INCORRECT | K5: L08 | L5: A.sqrt(3) / (T/3) == 9.A/T. | M5: Symbolic_Simplification_Error (3*sqrt(3)*A/T != 9*A/T) | N5: Dòng L08 có vấn đề. Học sinh đã nhầm lẫn trong việc tính thời gian \(\Delta t\). Theo lời giải chuẩn, thời gian \(\Delta t\) mà vật ở vùng \(\left| x \right| \leq \frac{A\sqrt{3}}{2}\) trong nửa chu kì là \(\frac{T}{3}\), không phải \(\frac{T}{6}\). Do đó, biểu thức \(\frac{A\sqrt{3}}{\frac{T}{3}}\) nên được viết lại là \(3A\sqrt{3} \cdot \frac{1}{T}\). Học sinh hãy kiểm tra lại công thức tính thời gian \(\Delta t\) và quãng đường \(S\) trong bước này, sau đó tính lại tốc độ trung bình \(v_{tb}\)? | O5: 1 | P5: 1 | Q5: 1
A6: sub_05 | B6: q_19 | C6: Calibration_11Q | D6: INCORRECT | E6: Học sinh viết \( W = 0,02 + 0,1125\pi \, \text{J} \) nhưng Lời giải mẫu là \( W = 0,245 \, \text{J} \). | F6: Học sinh cần tính toán lại động năng ban đầu \( W_d \) đúng theo công thức và giá trị đã cho. Động năng ban đầu \( W_d = \frac{1}{2} \times 0.4 \times (0.15\sqrt{5}\pi)^2 \), sau đó cộng với thế năng ban đầu \( W_t = 0.02 \, \text{J} \) để được năng lượng dao động \( W = 0.245 \, \text{J} \). | G6: 0 | H6: 1 | I6: 2 | J6: INCORRECT | K6: L05 | L6: W == 50.(0,0004) + 0,2.(0,0225 * 5π) | M6: Sequential_Value_Drift (W: prev=0.02 + 0.0225*pi**2 vs new=0.02 + 0.0225*pi) | N6: Dòng L05 có vấn đề. Theo lời giải chuẩn, tại L05 bạn nên giữ nguyên biểu thức động năng như sau: \( W_d = \frac{1}{2} \times 0.4 \times (0.15\sqrt{5}\pi)^2 \). Tuy nhiên, bạn đã thay đổi thành \( W_d = 50 \times (0.0004) + 0.2 \times (0.0225 \times 5\pi) \), khiến biểu thức không còn chính xác. Hãy kiểm tra lại công thức động năng và thay số đúng theo lời giải chuẩn. Bạn có thể làm lại từ đây? | O6: 1 | P6: 1 | Q6: 1
A7: sub_06 | B7: q_19 | C7: Calibration_11Q | D7: INCORRECT | E7: Học sinh viết \( W = 50 \times (0,0004) + 0,2 \times (0,225 \times 5 \times 10) \) nhưng Lời giải mẫu là \( W = \frac{1}{2} \times 100 \times (0.02)^2 + \frac{1}{2} \times 0.4 \times (0.15\sqrt{5}\pi)^2 \). | F7: Học sinh nên sử dụng công thức chính xác từ Lời giải mẫu: \( W = \frac{1}{2} \times 100 \times (0.02)^2 + \frac{1}{2} \times 0.4 \times (0.15\sqrt{5}\pi)^2 \). | G7: 1 | H7: 1 | I7: 1 | J7: INCORRECT | K7: L05 | L7: W == 50.(0,0004) + 0,2.(0,225 * 5 * 10) | M7: Sequential_Value_Drift (W: prev=0.02 + 0.0225*pi**2 vs new=2.27000000000000) | N7: Dòng L05 có vấn đề. Theo lời giải chuẩn, biểu thức tại L05 nên là \( W = 50 \times (0.0004) + 0.2 \times (0.225 \times 5 \times 10) \), nhưng học sinh đã nhầm lẫn và viết thành \( W = 50 \times (0.0004) + 0.2 \times (0.225 \times 5 \times 10) \). Điều này khiến kết quả không chính xác. Hãy kiểm tra lại từng bước tính toán và so sánh với công thức chuẩn. Bạn đã làm gì khác biệt ở đây? ? | O7: 1 | P7: 1 | Q7: 1
A8: sub_07 | B8: q_20 | C8: HeldOut_Unseen_11Q | D8: INCORRECT | E8: Học sinh viết \( W_{\text{đmax}} = \frac{1}{2} \cdot 0.05 \cdot 3^2 \cdot 0.04^2 \) nhưng Lời giải mẫu là \( W_{\text{đmax}} = \frac{1}{2} \cdot 0.05 \cdot (0.12)^2 \). | F8: Học sinh nên sử dụng công thức \( W_{\text{đmax}} = \frac{1}{2} m v_{\text{max}}^2 \) thay vì \( W_{\text{đmax}} = \frac{1}{2} m \omega^2 A^2 \). Vận tốc cực đại \( v_{\text{max}} \) đã được tính trước đó là \( 0.12 \, \text{m/s} \). | G8: 0 | H8: 1 | I8: 1 | J8: INCORRECT | K8: L06 | L8: Wd_max == 0,00225 (J). | M8: Sequential_Value_Drift (Wd_max: prev=0.000360000000000000 vs new=0.00225000000000000) | N8: Dòng L06 có lỗi. Theo công thức của lời giải chuẩn Stage 1, động năng cực đại \( W_{\text{đmax}} \) được tính bằng công thức \( W_{\text{đmax}} = \frac{1}{2} m v_{\text{max}}^2 \), trong đó \( v_{\text{max}} = \omega A \). Học sinh đã sử dụng công thức này nhưng có sự nhầm lẫn trong quá trình tính toán. Hãy kiểm tra lại phép tính của bạn và so sánh với công thức \( W_{\text{đmax}} = \frac{1}{2} \times 0.05 \times (0.12)^2 \)? | O8: 1 | P8: 1 | Q8: 1
A9: sub_08 | B9: q_22 | C9: Calibration_11Q | D9: INCORRECT | E9: Học sinh viết \(\alpha_0^2 = \frac{0.441}{78.4}\) nhưng Lời giải mẫu là \(\alpha_0^2 = \frac{0.441}{78.4}\). (Bước này tương đương toán học.) | F9: Không cần sửa, vì biểu thức của học sinh và Lời giải mẫu là giống nhau. | G9: 0 | H9: 0 | I9: 1 | J9: INCORRECT | K9: L05 | L9: alpha0^2 == 0,00565625. | M9: IntraStep_Calc_Error (9/1600 != 0.00565625000000000, Numeric_Mismatch(diff=3.125e-05,tol=1.00e-06)) | N9: Dòng L05 có vấn đề. Theo công thức chuẩn, bạn đã tính được \(\alpha_0^2 = \frac{0.441}{78.4}\), nhưng kết quả bạn đưa ra là \(\alpha_0^2 = 0.00565625\). Thực tế, \(\frac{0.441}{78.4}\) sẽ cho kết quả khác. Hãy kiểm tra lại phép chia này và xem liệu bạn có làm tròn sai hay không? ? Hãy tính lại \(\frac{0.441}{78.4}\) và so sánh với kết quả bạn đã có. | O9: 1 | P9: 1 | Q9: 1
A10: sub_09 | B10: q_25 | C10: HeldOut_Unseen_11Q | D10: INCORRECT | E10: Học sinh viết \( \frac{A'}{A} = \sqrt{0.92} \approx 0.9539 \) nhưng Lời giải mẫu là \( \frac{A'}{A} = \sqrt{0.92} \approx 0.9592 \). | F10: Sử dụng giá trị từ Lời giải mẫu, ta có \( \sqrt{0.92} \approx 0.9592 \). | G10: 1 | H10: 1 | I10: 2 | J10: INCORRECT | K10: L02 | L10: sqrt(0,92) == 0,9539. | M10: IntraStep_Calc_Error (0.959166304662544 != 0.953900000000000, Numeric_Mismatch(diff=0.0052663,tol=5.50e-05)) | N10: Dòng L02 có vấn đề. Theo công thức trong Lời giải chuẩn Stage 1, bạn cần tính tỉ số biên độ còn lại như sau: \( \frac{A'}{A} = \sqrt{\frac{W'}{W}} = \sqrt{0.92} \). Giá trị chính xác của \( \sqrt{0.92} \) là khoảng 0.9592, không phải 0.9539. Hãy thử tính lại giá trị của \( \sqrt{0.92} \) và xem kết quả có thay đổi không? ? | O10: 1 | P10: 1 | Q10: 1
A11: sub_10 | B11: q_25 | C11: HeldOut_Unseen_11Q | D11: INCORRECT | E11: Học sinh viết \( \frac{A'}{A} \approx 0.9583 \) nhưng Lời giải mẫu là \( \frac{A'}{A} \approx 0.9592 \). | F11: Sử dụng giá trị từ Lời giải mẫu, hãy thay đổi \( 0.9583 \) thành \( 0.9592 \). | G11: 1 | H11: 1 | I11: 2 | J11: INCORRECT | K11: L03 | L11: sqrt(0,92) == 0,9583. | M11: IntraStep_Calc_Error (0.959166304662544 != 0.958300000000000, Numeric_Mismatch(diff=0.0008663,tol=5.50e-05)) | N11: Dòng L03 có vấn đề. Theo lời giải chuẩn, bạn đã tính đúng rằng \( \frac{A'}{A} = \sqrt{0.92} \). Tuy nhiên, khi tính giá trị căn bậc hai của 0.92, bạn đã làm tròn sai. Giá trị chính xác của \( \sqrt{0.92} \) là khoảng 0.9592, không phải 0.9583. Điều này khiến phần trăm biên độ giảm đi không chính xác. Hãy thử tính lại \( \sqrt{0.92} \) và làm tròn đến 4 chữ số thập phân, sau đó tính phần trăm biên độ giảm đi? | O11: 1 | P11: 1 | Q11: 1
A12: sub_11 | B12: q_26 | C12: Calibration_11Q | D12: INCORRECT | E12: Học sinh viết \(\Delta t = t_1 + T = \frac{T}{6} + T = \frac{7T}{6} = \frac{7 \cdot 1}{6} = 1.167\) (s) nhưng Lời giải mẫu là \(\Delta t = t_1 + T = \frac{T}{6} + T = 0.167 + 1 = 1.167\) (s). | F12: Học sinh nên sử dụng giá trị \(t_1 = \frac{T}{6} = \frac{1}{6} \approx 0.167\) (s) thay vào công thức \(\Delta t = t_1 + T\). | G12: 0 | H12: 1 | I12: 1 | J12: INCORRECT | K12: L10 | L12: 31,5 / 1,167 == 27,19 (cm/s). | M12: IntraStep_Calc_Error (26.9922879177378 != 27.1900000000000, Numeric_Mismatch(diff=0.19771,tol=5.50e-03)) | N12: Dòng L10: Tại đây, em đã tính tốc độ trung bình \( v_{\text{tb}} \) bằng cách chia quãng đường \( S = 31.5 \) cm cho thời gian \( \Delta t = 1.167 \) s, nhưng kết quả em được \( 27.19 \) cm/s thay vì \( 27 \) cm/s. Theo công thức của lời giải chuẩn, tốc độ trung bình \( v_{\text{tb}} \) được tính như sau: \[ v_{\text{tb}} = \frac{S}{\Delta t} = \frac{31.5}{1.167} \approx 27 \text{ cm/s} \] Em đã làm tròn sai số. Hãy thử làm tròn kết quả của phép chia \( 31.5 \div 1.167 \) sao cho kết quả chính xác nhất có 2 chữ số thập phân? | O12: 1 | P12: 1 | Q12: 1
A13: sub_12 | B13: q_26 | C13: Calibration_11Q | D13: INCORRECT | E13: Học sinh viết \(\Delta t = \frac{7T}{6} = \frac{7 \cdot 1}{6} = \frac{7}{6} \text{ s}\) nhưng Lời giải mẫu là \(\Delta t = t_1 + T = \frac{T}{6} + T = \frac{1}{6} + 1 = 1.167 \text{ s}\). | F13: Theo Lời giải mẫu, thời gian \(\Delta t\) từ khi qua vị trí \(x_0\) đến khi gia tốc đạt giá trị cực tiểu lần thứ hai là \(t_1 + T = \frac{T}{6} + T = \frac{1}{6} + 1 = 1.167 \text{ s}\). | G13: 0 | H13: 1 | I13: 1 | J13: INCORRECT | K13: L10 | L13: 31,5 / 7/6 == 25,5 (cm/s). | M13: IntraStep_Calc_Error (27.0000000000000 != 25.5000000000000, Numeric_Mismatch(diff=1.5,tol=5.50e-02)) | N13: Dòng L10 có lỗi vì học sinh đã làm tròn sai số trong phép chia. Theo công thức chuẩn, quãng đường \( S = 31.5 \) cm và thời gian \( \Delta t = \frac{7}{6} \) s. Khi tính tốc độ trung bình \( v_{\text{tb}} \), học sinh nên giữ nguyên số thập phân để tránh sai số: \[ v_{\text{tb}} = \frac{31.5}{\frac{7}{6}} = 31.5 \times \frac{6}{7} = 27 \text{ cm/s} \] Học sinh cần chú ý giữ nguyên số thập phân trong phép chia để tránh sai số. Hãy thử tính lại và kiểm tra kết quả? | O13: 1 | P13: 1 | Q13: 1
A14: sub_13 | B14: q_28 | C14: HeldOut_Unseen_11Q | D14: INCORRECT | E14: Học sinh viết \(\omega = \frac{2\pi}{60} = \frac{\pi}{30} \text{ rad/s}\) và \(T = 60 \text{ s}\), nhưng Lời giải mẫu là \(\omega = \frac{200\pi}{60} = \frac{10\pi}{3} \text{ rad/s}\) và \(T = 0.6 \text{ s}\). | F14: Học sinh cần sử dụng công thức \(\omega = \frac{a_{\text{max}}}{v_{\text{max}}}\) với đơn vị thống nhất (cm/s và cm/s^2), và \(\omega = \frac{2\pi}{T}\) để tính đúng tần số góc và chu kỳ. | G14: 1 | H14: 1 | I14: 3 | J14: INCORRECT | K14: L01 | L14: a_max / v_max == 2.pi / 60 | M14: IntraStep_Calc_Error (10*pi/3 != pi/30, Numeric_Mismatch(diff=10.367,tol=1.00e-06)) | N14: Dòng L01 có lỗi. Theo công thức trong Lời giải chuẩn Stage 1, tần số góc \(\omega\) được tính bằng cách chia gia tốc cực đại \(a_{\text{max}}\) cho vận tốc cực đại \(v_{\text{max}}\). Cụ thể, \(\omega = \frac{a_{\text{max}}}{v_{\text{max}}} = \frac{2\pi \text{ m/s}^2}{60 \text{ cm/s}} = \frac{2\pi \times 100 \text{ cm/s}^2}{60 \text{ cm/s}} = \frac{200\pi}{60} \text{ rad/s} = \frac{10\pi}{3} \text{ rad/s}\). Vì vậy, học sinh đã làm tròn sai hoặc bỏ qua đơn vị chuyển đổi, dẫn đến kết quả \(\omega = \frac{\pi}{30} \text{ rad/s}\) thay vì \(\omega = \frac{10\pi}{3} \text{ rad/s}\). Hãy kiểm tra lại phép tính và đảm bảo giữ nguyên đơn vị trong quá trình tính toán? ? | O14: 1 | P14: 1 | Q14: 1
A15: sub_14 | B15: q_28 | C15: HeldOut_Unseen_11Q | D15: INCORRECT | E15: Học sinh viết \(t = \frac{5T}{12}\) nhưng Lời giải mẫu là \(t = \frac{T}{12} + \frac{T}{4} + \frac{T}{12} = \frac{5T}{12}\). Tuy nhiên, học sinh đã tính sai tổng thời gian di chuyển, kết quả là \(t = 0.3\) s thay vì \(t = 0.25\) s. | F15: Hãy tính tổng thời gian di chuyển theo từng đoạn như trong Lời giải mẫu: \(t = \frac{T}{12} + \frac{T}{4} + \frac{T}{12} = \frac{5T}{12}\). Thay số \(T = 0.6\) s vào để được \(t = 0.25\) s. | G15: 1 | H15: 1 | I15: 3 | J15: INCORRECT | K15: L11 | L15: \frac{5 \times 0.6}{12} == \frac{3}{10} | M15: IntraStep_Calc_Error (0.250000000000000 != 3/10, Numeric_Mismatch(diff=0.05,tol=1.00e-06)) | N15: Dòng L11: Em đã tính tổng thời gian di chuyển là \(\frac{5 \times 0.6}{12} = \frac{3}{10} = 0.3\) s. Tuy nhiên, theo công thức Lời giải chuẩn, tổng thời gian di chuyển là \(\frac{5T}{12}\). Hãy kiểm tra lại phép tính của em, đặc biệt là cách em chia 5 cho 12 và nhân với 0.6. Tại sao em lại được \(\frac{3}{10}\) thay vì \(\frac{5}{12}\)? ? | O15: 1 | P15: 1 | Q15: 1
... A32: sub_31 | B32: q_40 | C32: HeldOut_Unseen_11Q | D32: INCORRECT | E32: Học sinh viết \(10\pi t = -\frac{\pi}{6} + \frac{\pi}{6} + 2k\pi\) nhưng Lời giải mẫu là \(10\pi t = -\frac{\pi}{3} + 2k\pi\). | F32: Học sinh nên sử dụng pha ban đầu từ Lời giải mẫu là \(-\frac{\pi}{3}\) thay vì \(-\frac{\pi}{6}\). | G32: 0 | H32: 0 | I32: 1 | J32: INCORRECT | K32: L03 | L32: 40π.cos(10πt - π/3 + π/2) == 40π.cos(10πt - π/6). | M32: Wave_Transform_Error (Symbolic_Mismatch) | N32: Dòng L03 của em có vấn đề. Em đã chuyển đổi từ biểu thức vận tốc \( v = -40\pi \sin(10\pi t - \frac{\pi}{3}) \) sang \( v = 40\pi \cos(10\pi t - \frac{\pi}{3} + \frac{\pi}{2}) \), nhưng theo công thức chuẩn, biểu thức đúng là \( v = 40\pi \cos(10\pi t - \frac{\pi}{6}) \). Điều này xảy ra do em đã cộng sai góc. Hãy kiểm tra lại quy tắc chuyển đổi giữa sin và cos, và nhớ rằng \( \sin(x) = \cos(x - \frac{\pi}{2}) \). Em có thể làm lại bước này không? | O32: 1 | P32: 1 | Q32: 1

Sheet 8_Blind_Human_Grading_Form
A1: submission_id | B1: question_id | C1: true_first_error_lines | D1: student_numbered_lines | E1: Tutor_A_Feedback | F1: Tutor_A_Faithful_0_1 | G1: Tutor_A_Usefulness_1_3 | H1: Tutor_B_Feedback | I1: Tutor_B_Faithful_0_1 | J1: Tutor_B_Usefulness_1_3
A2: sub_01 | B2: q_04 | C2: L04 | D2: L01: Trong dao động điều hòa, khoảng thời gian giữa hai lần liên tiếp vật đi qua vị trí cân bằng là nửa chu kỳ ($\Delta t = T/2$). L02: Từ phương trình dao động, ta có tần số góc $\omega = 4\pi \text{ rad/s}$. L03: Khoảng thời gian giữa hai lần liên tiếp vật qua vị trí cân bằng là: L04: $\Delta t = \frac{T}{2} = \frac{2\pi}{\omega \cdot 2} = \frac{\pi}{4\pi} = 0,125 \text{ (s)}$ L05: Khoảng thời gian giữa hai lần liên tiếp vật qua vị trí cân bằng là $\Delta t = 0,125 \text{ s}$. | E2: Dòng L04 có lỗi ở chỗ học sinh đã thực hiện phép chia \(\frac{\pi}{4\pi}\) và thu được kết quả \(0.125\) thay vì \(0.25\). Theo công thức chuẩn, chu kỳ \(T\) của dao động là \(\frac{2\pi}{\omega}\), và khoảng thời gian giữa hai lần liên tiếp vật đi qua VTCB là \(\Delta t = \frac{T}{2} = \frac{\pi}{\omega}\). Vì vậy, khi thay \(\omega = 4\pi\) vào, ta sẽ có \(\Delta t = \frac{\pi}{4\pi} = \frac{1}{4} = 0.25\) s. Hãy kiểm tra lại phép tính của bạn và xem liệu bạn có làm tròn sai hay không? ? | F2: 1 | G2: 3 | H2: Học sinh nên sử dụng công thức $\Delta t = \frac{\pi}{\omega}$ thay vì $\Delta t = \frac{2\pi}{\omega \cdot 2}$. | I2: 0 | J2: 1
A3: sub_02 | B3: q_08 | C3: L01,L02 | D3: L01: Biên độ dao động \( A \) được tính thông qua mối quan hệ giữa vận tốc cực đại \( v_{max} \) và gia tốc cực đại \( a_{max} \). Theo công thức \( a_{max} = \omega^2 A \) và \( v_{max} = \omega A \), chúng ta có thể viết \( a_{max} = (\frac{v_{max}}{\omega})^2 \). L02: - Từ \( a_{max} = 16\pi^2 \) cm/s², ta có thể giải \( \omega^2 = \frac{a_{max}}{v_{max}} = \frac{16\pi^2}{8\pi} = 2\pi^2 \). L03: - Từ đó, \( \omega = \sqrt{2\pi^2} = 2\pi \) rad/s. L04: - Sử dụng \( v_{max} = \omega A \), ta có \( 8\pi = 2\pi A \), từ đó \( A = 4 \) cm. L05: Biên độ của dao động là \( A = 4 \) cm. | E3: Không cần sửa gì. | F3: 0 | G3: 1 | H3: Dòng L01 của em có vấn đề. Em đã viết \( a_{max} = \left(\frac{v_{max}}{\omega}\right)^2 \), nhưng theo lời giải chuẩn, công thức đúng là \( a_{max} = \omega^2 A \). Vì vậy, em nên sử dụng mối quan hệ giữa \( a_{max} \), \( \omega \), và \( A \) để tìm \( \omega \) trước. Cụ thể, em có thể viết \( \omega^2 = \frac{a_{max}}{A} \). Vậy, em hãy thử lại từ đây xem sao? | I3: 1 | J3: 1
A4: sub_03 | B4: q_10 | C4: L02 | D4: L01: Phương trình x1 ở dạng sin nên cần chuẩn hóa về dạng cos để xác định các thông số và tính biên độ tổng hợp A, từ đó tìm v_max. L02: - Chuẩn hóa x1: x1 = 3cos(10t – π/3 + π/2) = 3cos(10t + π/6) cm. L03: - Thông số: A1 = 3 cm, phi1 = π/6 rad; A2 = 4 cm, phi2 = π/6 rad; omega = 10 rad/s. L04: - Độ lệch pha: delta_phi = φ2 - φ1 = π/6 - π/6 = 0 rad. L05: - Biên độ tổng hợp: A = √(3^2 + 4^2 + 2.3.4.cos(0)) = √(9 + 16 + 24) = √49 = 7 cm. L06: - Tốc độ cực đại: v_max = ω.A = 10 . 7 = 70 (cm/s). L07: Tốc độ cực đại của vật là v_max = 70 cm/s. | E4: Học sinh cần lưu ý rằng độ lệch pha \( \Delta \phi = \pi \) rad, nên \( \cos(\Delta \phi) = \cos(\pi) = -1 \). Do đó, biểu thức cho biên độ tổng hợp \( A \) phải là \( A = \sqrt{9 + 16 + 2 \cdot 3 \cdot 4 \cdot (-1)} = \sqrt{1} = 1 \) cm. | F4: 0 | G4: 1 | H4: Dòng L02 có vấn đề. Học sinh đã chuẩn hóa phương trình \( x_1 \) thành \( 3\cos(10t - \frac{\pi}{3} + \frac{\pi}{2}) \), nhưng theo công thức chuẩn, ta cần cộng thêm \( \frac{\pi}{2} \) vào pha của \( x_1 \) để chuyển nó sang dạng cos. Tuy nhiên, học sinh đã cộng \( \frac{\pi}{2} \) vào pha \( -\frac{\pi}{3} \) mà không đổi dấu, dẫn đến sai lệch. Theo công thức chuẩn, pha của \( x_1 \) sau khi chuẩn hóa nên là \( -\frac{\pi}{3} - \frac{\pi}{2} = -\frac{5\pi}{6} \). Hãy kiểm tra lại và viết lại pha của \( x_1 \) sao cho nó đúng theo công thức chuẩn, rồi tiếp tục tính toán nhé? | I4: 1 | J4: 2
A5: sub_04 | B5: q_17 | C5: L08 | D5: L01: - Điều kiện đề bài: Wt <= 3.Wđ. L02: - Ta có cơ năng W = Wt + Wđ = Wt + 3.Wt = 4.Wt => Wt/W <= 3/4. L03: - Theo công thức thế năng: Wt/W = x^2/A^2 => x^2/A^2 <= 3/4 => |x| <= A.sqrt(3)/2. L04: - Như vậy, vùng cần xét là khoảng li độ trong đoạn [-A.sqrt(3)/2, A.sqrt(3)/2]. L05: - Thời gian đi từ VTCB (x = 0) đến x = A.sqrt(3)/2 là T/6. L06: - Trong nửa chu kỳ (T/2), thời gian vật ở vùng |x| <= A.sqrt(3)/2 là: delta_t = 2.(T/6) = T/3. L07: - Quãng đường tương ứng đi từ -A.sqrt(3)/2 đến A.sqrt(3)/2 là: S = A.sqrt(3). L08: - Tốc độ trung bình: v_tb = S/delta_t = A.sqrt(3) / (T/3) = 9.A/T. L09: - Thay số: 300.sqrt(3) = 9.A/T => A/T = 33.33. L10: - Tốc độ cực đại: v_max = 2.pi.(A/T) = 2.pi.33.33 = 213.06.pi (cm/s). L11: Tốc độ cực đại là v_max = 213.06.pi (cm/s). | E5: Dòng L08 có vấn đề. Học sinh đã nhầm lẫn trong việc tính thời gian \(\Delta t\). Theo lời giải chuẩn, thời gian \(\Delta t\) mà vật ở vùng \(\left| x \right| \leq \frac{A\sqrt{3}}{2}\) trong nửa chu kì là \(\frac{T}{3}\), không phải \(\frac{T}{6}\). Do đó, biểu thức \(\frac{A\sqrt{3}}{\frac{T}{3}}\) nên được viết lại là \(3A\sqrt{3} \cdot \frac{1}{T}\). Học sinh hãy kiểm tra lại công thức tính thời gian \(\Delta t\) và quãng đường \(S\) trong bước này, sau đó tính lại tốc độ trung bình \(v_{tb}\)? | F5: 0 | G5: 2 | H5: Học sinh nên sử dụng công thức \( v_{tb} = \frac{S}{\Delta t} = \frac{A\sqrt{3}}{\frac{T}{3}} = 3A\sqrt{3}/T \) như trong Lời giải mẫu. | I5: 1 | J5: 2
A6: sub_05 | B6: q_19 | C6: L05 | D6: L01: Năng lượng dao động (Cơ năng, W) của vật được bảo toàn và bằng tổng của thế năng và động năng của vật tại thời điểm ban đầu (W = 1/2.k.x0^2 + 1/2.m.v0^2). L02: - Chuyển đổi đơn vị: x0 = 2 cm = 0,02 m; v0 = 15√5π cm/s = 0,15√5π m/s. L03: - Công thức: W = 1/2.k.x0^2 + 1/2.m.v0^2. L04: - Thay số: W = 1/2.(100).(0,02)^2 + 1/2.(0,4).(0,15√5π)^2 L05: W = 50.(0,0004) + 0,2.(0,0225 * 5π) L06: W = 0,02 + 0,2.(0,1125 * 5π) L07: W = 0,02 + 0,2.(0,5625π) L08: W = 0,02 + 0,1125π (J). L09: Năng lượng dao động của vật là W = 0,02 + 0,1125π (J). | E6: Học sinh cần tính toán lại động năng ban đầu \( W_d \) đúng theo công thức và giá trị đã cho. Động năng ban đầu \( W_d = \frac{1}{2} \times 0.4 \times (0.15\sqrt{5}\pi)^2 \), sau đó cộng với thế năng ban đầu \( W_t = 0.02 \, \text{J} \) để được năng lượng dao động \( W = 0.245 \, \text{J} \). | F6: 0 | G6: 1 | H6: Dòng L05 có vấn đề. Theo lời giải chuẩn, tại L05 bạn nên giữ nguyên biểu thức động năng như sau: \( W_d = \frac{1}{2} \times 0.4 \times (0.15\sqrt{5}\pi)^2 \). Tuy nhiên, bạn đã thay đổi thành \( W_d = 50 \times (0.0004) + 0.2 \times (0.0225 \times 5\pi) \), khiến biểu thức không còn chính xác. Hãy kiểm tra lại công thức động năng và thay số đúng theo lời giải chuẩn. Bạn có thể làm lại từ đây? | I6: 0 | J6: 2
A7: sub_06 | B7: q_19 | C7: L05 | D7: L01: Năng lượng dao động (Cơ năng, W) của vật được bảo toàn và bằng tổng của thế năng và động năng của vật tại thời điểm ban đầu (W = 1/2.k.x0^2 + 1/2.m.v0^2). L02: - Chuyển đổi đơn vị: x0 = 2 cm = 0,02 m; v0 = 15√5π cm/s = 15√5.pi / 100 m/s = 0,15√5.pi m/s. L03: - Công thức: W = 1/2.k.x0^2 + 1/2.m.v0^2. L04: - Thay số: W = 1/2.(100).(0,02)^2 + 1/2.(0,4).(0,15√5.pi)^2 L05: W = 50.(0,0004) + 0,2.(0,225 * 5 * 10) L06: W = 0,002 + 0,275 = 0,277 (J). L07: Năng lượng dao động của vật là W = 0,277 (J). | E7: Học sinh nên sử dụng công thức chính xác từ Lời giải mẫu: \( W = \frac{1}{2} \times 100 \times (0.02)^2 + \frac{1}{2} \times 0.4 \times (0.15\sqrt{5}\pi)^2 \). | F7: 0 | G7: 1 | H7: Dòng L05 có vấn đề. Theo lời giải chuẩn, biểu thức tại L05 nên là \( W = 50 \times (0.0004) + 0.2 \times (0.225 \times 5 \times 10) \), nhưng học sinh đã nhầm lẫn và viết thành \( W = 50 \times (0.0004) + 0.2 \times (0.225 \times 5 \times 10) \). Điều này khiến kết quả không chính xác. Hãy kiểm tra lại từng bước tính toán và so sánh với công thức chuẩn. Bạn đã làm gì khác biệt ở đây? ? | I7: 0 | J7: 1
A8: sub_07 | B8: q_20 | C8: L06 | D8: L01: Động năng cực đại (Wđmax) của vật trong dao động điều hòa bằng cơ năng (W) của hệ và được tính bằng công thức Wđmax = 1/2.m.vmax^2, với vmax = omega.A. L02: - Chuyển đổi đơn vị: m = 50 g = 0,05 kg; A = 4 cm = 0,04 m. L03: - Công thức: Wđmax = 1/2.m.omega^2.A^2. L04: - Thay số: Wđmax = 1/2.(0,05).(3)^2.(0,04)^2 L05: Wđmax = 0,025 * 9 * 0,0016 L06: Wđmax = 0,00225 (J). L07: Động năng cực đại của vật là Wđmax = 0,00225 (J). | E8: Học sinh nên sử dụng công thức \( W_{\text{đmax}} = \frac{1}{2} m v_{\text{max}}^2 \) thay vì \( W_{\text{đmax}} = \frac{1}{2} m \omega^2 A^2 \). Vận tốc cực đại \( v_{\text{max}} \) đã được tính trước đó là \( 0.12 \, \text{m/s} \). | F8: 0 | G8: 1 | H8: Dòng L06 có lỗi. Theo công thức của lời giải chuẩn Stage 1, động năng cực đại \( W_{\text{đmax}} \) được tính bằng công thức \( W_{\text{đmax}} = \frac{1}{2} m v_{\text{max}}^2 \), trong đó \( v_{\text{max}} = \omega A \). Học sinh đã sử dụng công thức này nhưng có sự nhầm lẫn trong quá trình tính toán. Hãy kiểm tra lại phép tính của bạn và so sánh với công thức \( W_{\text{đmax}} = \frac{1}{2} \times 0.05 \times (0.12)^2 \)? | I8: 1 | J8: 3
A9: sub_08 | B9: q_22 | C9: L05 | D9: L01: Với dao động nhỏ, cơ năng của con lắc đơn được xác định bởi công thức: W = 1/2 . m . g . l . alpha0^2, với alpha0 là biên độ góc (rad). L02: - Dữ kiện: m = 2 kg; l = 4 m; g = 9,8 m/s^2; W = 0,2205 J. L03: - Rút ra công thức: alpha0^2 = 2W / (m.g.l). L04: - Thay số: alpha0^2 = (2 . 0,2205) / (2 . 9,8 . 4) = 0,441 / 78,4. L05: - Kết quả trung gian: alpha0^2 = 0,00565625. L06: - Tính biên độ góc: alpha0 = sqrt(0,00565625) \approx 0,0752 (rad). L07: Biên độ góc của con lắc là alpha0 \approx 0,0752 rad. | E9: Không cần sửa, vì biểu thức của học sinh và Lời giải mẫu là giống nhau. | F9: 0 | G9: 1 | H9: Dòng L05 có vấn đề. Theo công thức chuẩn, bạn đã tính được \(\alpha_0^2 = \frac{0.441}{78.4}\), nhưng kết quả bạn đưa ra là \(\alpha_0^2 = 0.00565625\). Thực tế, \(\frac{0.441}{78.4}\) sẽ cho kết quả khác. Hãy kiểm tra lại phép chia này và xem liệu bạn có làm tròn sai hay không? ? Hãy tính lại \(\frac{0.441}{78.4}\) và so sánh với kết quả bạn đã có. | I9: 1 | J9: 3
A10: sub_09 | B10: q_25 | C10: L02 | D10: L01: Cơ năng của con lắc là W = 1/2 . k . A^2. Khi năng lượng mất đi 8%, phần năng lượng còn lại là W' = 92% . W = 0,92 . W. L02: - Tỉ số biên độ còn lại: A'/A = sqrt(W'/W) = sqrt(0,92) ≈ 0,9539. L03: - Phần trăm biên độ giảm: %delta_A = (1 - 0,9539) . 100% ≈ 4,61%. L04: Biên độ giảm đi khoảng 4,61%. | E10: Dòng L02 có vấn đề. Theo công thức trong Lời giải chuẩn Stage 1, bạn cần tính tỉ số biên độ còn lại như sau: \( \frac{A'}{A} = \sqrt{\frac{W'}{W}} = \sqrt{0.92} \). Giá trị chính xác của \( \sqrt{0.92} \) là khoảng 0.9592, không phải 0.9539. Hãy thử tính lại giá trị của \( \sqrt{0.92} \) và xem kết quả có thay đổi không? ? | F10: 1 | G10: 3 | H10: Sử dụng giá trị từ Lời giải mẫu, ta có \( \sqrt{0.92} \approx 0.9592 \). | I10: 1 | J10: 2
A11: sub_10 | B11: q_25 | C11: L03 | D11: L01: Cơ năng của con lắc tỉ lệ với bình phương biên độ (W = 1/2 . k . A^2). Khi năng lượng mất đi 8%, phần năng lượng còn lại là W' = 92% . W = 0,92 . W. L02: - Tỉ số biên độ còn lại: A'/A = sqrt(W'/W) = sqrt(0,92). L03: - Tính giá trị tỉ số A'/A: A'/A ≈ sqrt(0,92) ≈ 0,9583. L04: - Phần trăm biên độ giảm: %delta_A = (1 - 0,9583) . 100% ≈ 4,17%. L05: Biên độ giảm đi 4,17%. | E11: Sử dụng giá trị từ Lời giải mẫu, hãy thay đổi \( 0.9583 \) thành \( 0.9592 \). | F11: 1 | G11: 2 | H11: Dòng L03 có vấn đề. Theo lời giải chuẩn, bạn đã tính đúng rằng \( \frac{A'}{A} = \sqrt{0.92} \). Tuy nhiên, khi tính giá trị căn bậc hai của 0.92, bạn đã làm tròn sai. Giá trị chính xác của \( \sqrt{0.92} \) là khoảng 0.9592, không phải 0.9583. Điều này khiến phần trăm biên độ giảm đi không chính xác. Hãy thử tính lại \( \sqrt{0.92} \) và làm tròn đến 4 chữ số thập phân, sau đó tính phần trăm biên độ giảm đi? | I11: 1 | J11: 3
A12: sub_11 | B12: q_26 | C12: L10 | D12: L01: - Biên độ: A = L/2 = 14/2 = 7 cm. L02: - Vị trí đầu: x = 3,5 cm = A/2. Vật đang đi theo chiều dương. L03: - Vị trí đích: Gia tốc cực tiểu (amin) khi vật ở biên dương x = +A = 7 cm. L04: - Hành trình lần đầu: Từ vị trí x = A/2 theo chiều dương, vật đi trực tiếp ra biên dương (+A) để đạt đích lần thứ nhất. L05: - Thời gian t1: Thời gian vật đi từ A/2 đến A tương ứng với t1 = T/6. L06: - Quãng đường lẻ lần đầu: S1 = A - A/2 = 7 - 3,5 = 3,5 cm. L07: - Để đạt gia tốc cực tiểu lần thứ hai, vật đi thêm 1 chu kỳ T: L08: + delta_t = t1 + T = T/6 + T = 7T/6 = (7 . 1) / 6 = 1,167 (s). L09: + S = S1 + 4A = 3,5 + 4 . 7 = 31,5 cm. L10: - Tốc độ trung bình: v_tb = S / delta_t = 31,5 / 1,167 \approx 27,19 (cm/s). L11: Tốc độ trung bình là v_tb \approx 27,19 cm/s. | E12: Dòng L10: Tại đây, em đã tính tốc độ trung bình \( v_{\text{tb}} \) bằng cách chia quãng đường \( S = 31.5 \) cm cho thời gian \( \Delta t = 1.167 \) s, nhưng kết quả em được \( 27.19 \) cm/s thay vì \( 27 \) cm/s. Theo công thức của lời giải chuẩn, tốc độ trung bình \( v_{\text{tb}} \) được tính như sau: \[ v_{\text{tb}} = \frac{S}{\Delta t} = \frac{31.5}{1.167} \approx 27 \text{ cm/s} \] Em đã làm tròn sai số. Hãy thử làm tròn kết quả của phép chia \( 31.5 \div 1.167 \) sao cho kết quả chính xác nhất có 2 chữ số thập phân? | F12: 1 | G12: 2 | H12: Học sinh nên sử dụng giá trị \(t_1 = \frac{T}{6} = \frac{1}{6} \approx 0.167\) (s) thay vào công thức \(\Delta t = t_1 + T\). | I12: 0 | J12: 1
A13: sub_12 | B13: q_26 | C13: L10 | D13: L01: - Biên độ: A = L/2 = 14/2 = 7 cm. L02: - Vị trí đầu: x = 3,5 cm = A/2. Vật đang đi theo chiều dương. L03: - Vị trí đích: Gia tốc cực tiểu (amin) khi vật ở biên dương x = +A = 7 cm. L04: - Hành trình lần đầu: Từ x = A/2, vật đi theo chiều dương nên tiến thẳng đến biên dương (+A) là chạm đích lần 1. L05: - Thời gian t1: Khoảng thời gian vật đi thẳng từ A/2 đến A là t1 = T/6. L06: - Quãng đường lẻ lần đầu: S1 = A - A/2 = 7 - 3,5 = 3,5 cm. L07: - Lần thứ hai nên vật thực hiện thêm 1 chu kỳ T sau khi đã đến đích lần 1: L08: + delta_t = t1 + T = T/6 + T = 7T/6 = (7 . 1) / 6 = 7/6 (s). L09: + S = S1 + 4A = 3,5 + 4 . 7 = 3,5 + 28 = 31,5 cm. L10: - Tốc độ trung bình: v_tb = S / delta_t = 31,5 / 7/6 \approx 25,5 (cm/s). L11: Tốc độ trung bình là v_tb \approx 25,5 cm/s. | E13: Dòng L10 có lỗi vì học sinh đã làm tròn sai số trong phép chia. Theo công thức chuẩn, quãng đường \( S = 31.5 \) cm và thời gian \( \Delta t = \frac{7}{6} \) s. Khi tính tốc độ trung bình \( v_{\text{tb}} \), học sinh nên giữ nguyên số thập phân để tránh sai số: \[ v_{\text{tb}} = \frac{31.5}{\frac{7}{6}} = 31.5 \times \frac{6}{7} = 27 \text{ cm/s} \] Học sinh cần chú ý giữ nguyên số thập phân trong phép chia để tránh sai số. Hãy thử tính lại và kiểm tra kết quả? | F13: 1 | G13: 2 | H13: Theo Lời giải mẫu, thời gian \(\Delta t\) từ khi qua vị trí \(x_0\) đến khi gia tốc đạt giá trị cực tiểu lần thứ hai là \(t_1 + T = \frac{T}{6} + T = \frac{1}{6} + 1 = 1.167 \text{ s}\). | I13: 0 | J13: 1
